Workbook

Sheet Свод (2)
A1: Период | B1: Тип премирования | C1: Год | D1: Дата процедуры | E1: ИД сотрудника | F1: Должность | G1: Полный путь до подразделения | H1: Группа целей | I1: Наименование цели | J1: Описание цели/ожидаемый результат цели | K1: Название связанной цели/метки | L1: Тип цели | M1: Источник целей | N1: Название источника | O1: Должность из Каскад метрик_инвентаризация_28082026_ИВР
A2: 3 квартал 2026 | B2: Год + квартал | C2: 2026 | D2: 01.07.2026 - 30.09.2026 | E2: 1 | F2: Заместитель главного инженера | G2: Общество с ограниченной ответственностью "Томскнефтехим"/Направление Главного инженера/Направление заместителя главного инженера | H2: Базовые обязательства | I2: Средневзвешенная длительность реализации НБ проектов (I2I) | J2: не более 414 дней | K2: Выполнение целей стратегии устойчивого развития, % Не менее 100 % | L2: Количественная | M2: Контракт | N2: ТНХ 2026 | O2: =INDEX('список ID из СУЭ с должностями'!$A:$F,MATCH(E2,'список ID из СУЭ с должностями'!$B:$B,0),5) -> 0
A3: 3 квартал 2026 | B3: Год + квартал | C3: 2026 | D3: 01.07.2026 - 30.09.2026 | E3: 1 | F3: Заместитель главного инженера | G3: Общество с ограниченной ответственностью "Томскнефтехим"/Направление Главного инженера/Направление заместителя главного инженера | H3: Задачи с эффектом в текущем году | I3: Реализация проектов | J3: 1. «Тех.перевооружение: Установка налива ТИБА в танк контейнер 2. Реализация проекта ЦРП | K3: Успешное выполнение остановочного ремонта 2026 года | L3: Качественная | M3: Контракт | N3: ТНХ 2026 | O3: =INDEX('список ID из СУЭ с должностями'!$A:$F,MATCH(E3,'список ID из СУЭ с должностями'!$B:$B,0),5) -> 0
A4: 3 квартал 2026 | B4: Год + квартал | C4: 2026 | D4: 01.07.2026 - 30.09.2026 | E4: 1 | F4: Заместитель главного инженера | G4: Общество с ограниченной ответственностью "Томскнефтехим"/Направление Главного инженера/Направление заместителя главного инженера | H4: Базовые обязательства | I4: Подготовка и Выполнение остановочного ремонта согласно заявленным параметрам БП | J4: Подготовка и проведение ремонта по чек-листу не менее 95% | K4: Успешное выполнение остановочного ремонта 2026 года | L4: Качественная | M4: Контракт | N4: ТНХ 2026 | O4: =INDEX('список ID из СУЭ с должностями'!$A:$F,MATCH(E4,'список ID из СУЭ с должностями'!$B:$B,0),5) -> 0
A5: 3 квартал 2026 | B5: Год + квартал | C5: 2026 | D5: 01.07.2026 - 30.09.2026 | E5: 1 | F5: Заместитель главного инженера | G5: Общество с ограниченной ответственностью "Томскнефтехим"/Направление Главного инженера/Направление заместителя главного инженера | H5: Базовые обязательства | I5: Управление рабочим капиталом | J5: "Организация складского хранения: 1.нецелевые помещения освобождены и запломбированы 2.наведен порядок в целевых помещениях 3.установлен и соблюдается целевой процесс работы с МТР "" Соблюдение целевого уровня РК: Соблюдение общего уровня запасов РК на конец года в ЗО 3 121 млн.руб.: 1 373 млн.руб. СУОФ (МКЗ, МРП СУОФ, ЗИП) / 1 703 млн.руб СУН (АТЗ) / 45 млн.руб. МРП ИП Оборачиваемость МРП СУОФ текущего года поставки не более 90 дней Объем «срочных» заявок от общего годового объема не более 20% Подменный фонд к. 1027 разобран и поставлен на учет в систему до конца 3 кв. Избыточные запасы после проекта (Перевод в НВИ в течение 3 месяцев с даты закрытия проекта) - 0 руб." | K5: Выполнение ключевых финансово-экономических показателей | L5: Качественная | M5: Контракт | N5: ТНХ 2026 | O5: =INDEX('список ID из СУЭ с должностями'!$A:$F,MATCH(E5,'список ID из СУЭ с должностями'!$B:$B,0),5) -> 0
A6: 3 квартал 2026 | B6: Год + квартал | C6: 2026 | D6: 01.07.2026 - 30.09.2026 | E6: 1 | F6: Заместитель главного инженера | G6: Общество с ограниченной ответственностью "Томскнефтехим"/Направление Главного инженера/Направление заместителя главного инженера | H6: Базовые обязательства | I6: Исполнение/Не превышение бюджета ТОиР в рамках утвержденного БП | J6: не более 100 % | K6: Выполнение ключевых финансово-экономических показателей | L6: Количественная | M6: Контракт | N6: ТНХ 2026 | O6: =INDEX('список ID из СУЭ с должностями'!$A:$F,MATCH(E6,'список ID из СУЭ с должностями'!$B:$B,0),5) -> 0
A7: 3 квартал 2026 | B7: Год + квартал | C7: 2026 | D7: 01.07.2026 - 30.09.2026 | E7: 1 | F7: Заместитель главного инженера | G7: Общество с ограниченной ответственностью "Томскнефтехим"/Направление Главного инженера/Направление заместителя главного инженера | H7: Базовые обязательства | I7: Управление травматизмом | J7: "1. Полученные допуска по ГИ -100% 2. 0 событий в зоне ответственности с влиянием на Ltif предприятия 3. Кол-во ГОР и ОР в выходные дни не более 10% (отн. выход/будни) в среднем по предприятию. За исключением аварийных. | K7: Минимизация травматизма (LTIF) | L7: Качественная | M7: Контракт | N7: ТНХ 2026 | O7: =INDEX('список ID из СУЭ с должностями'!$A:$F,MATCH(E7,'список ID из СУЭ с должностями'!$B:$B,0),5) -> 0
A8: 3 квартал 2026 | B8: Год + квартал | C8: 2026 | D8: 01.07.2026 - 30.09.2026 | E8: 1 | F8: Заместитель главного инженера | G8: Общество с ограниченной ответственностью "Томскнефтехим"/Направление Главного инженера/Направление заместителя главного инженера | H8: Базовые обязательства | I8: Приживаемость метрик ПСС | J8: Ожидаемый результат не менее 90% Проведение внутренних аттестаций по результатам ЕКЭ РП и СУОФ (50% от общего объема) исполнение дорожной карты: Тираж Мини - Т Исполнение мероприятий проекта Сыгранность Мини-Т | K8: Обеспечить приживаемость Производственной системы | L8: Качественная | M8: Контракт | N8: ТНХ 2026 | O8: =INDEX('список ID из СУЭ с должностями'!$A:$F,MATCH(E8,'список ID из СУЭ с должностями'!$B:$B,0),5) -> 0
A9: 3 квартал 2026 | B9: Год + квартал | C9: 2026 | D9: 01.07.2026 - 30.09.2026 | E9: 2 | F9: Начальник смены производства | G9: Общество с ограниченной ответственностью "Томскнефтехим"/Направление Директора по производству/Производство полиэтилена/Смена 3 | H9: Долгосрочные цели | I9: Проведение Остановочного ремонта | J9: Организация проведения ОР (в ЗО): 1) в полном объеме 2) в установленный срок (согласно графика 4 уровня) 3) без нарушений требований безопасности (достаточность и полнота выполнения мероприятий по подготовке и проведению рабо) | K9: Успешное выполнение остановочного ремонта 2026 года | L9: Качественная | M9: Контракт | N9: ТНХ 2026 | O9: =INDEX('список ID из СУЭ с должностями'!$A:$F,MATCH(E9,'список ID из СУЭ с должностями'!$B:$B,0),5) -> НС
A10: 3 квартал 2026 | B10: Год + квартал | C10: 2026 | D10: 01.07.2026 - 30.09.2026 | E10: 2 | F10: Начальник смены производства | G10: Общество с ограниченной ответственностью "Томскнефтехим"/Направление Директора по производству/Производство полиэтилена/Смена 3 | H10: Базовые обязательства | I10: Выполнение целей стратегии устойчивого развития: | J10: 1. Выбросы ЗВ в атмосферу не более 0,225 2. Сбросы ЗВ в стоки не более 0,018 3. Отходы на размещение не более 0,050 4. Водопотребление, не более 21,7 5. Выбросы парниковых газов, не более 34,57 | K10: Выполнение целей стратегии устойчивого развития, % Не менее 100 % | L10: Качественная | M10: Контракт | N10: ТНХ 2026 | O10: =INDEX('список ID из СУЭ с должностями'!$A:$F,MATCH(E10,'список ID из СУЭ с должностями'!$B:$B,0),5) -> НС
A11: 3 квартал 2026 | B11: Год + квартал | C11: 2026 | D11: 01.07.2026 - 30.09.2026 | E11: 2 | F11: Начальник смены производства | G11: Общество с ограниченной ответственностью "Томскнефтехим"/Направление Директора по производству/Производство полиэтилена/Смена 3 | H11: Базовые обязательства | I11: Управление травматизмом (LTIF) и техногенностью ИА1,2 | J11: 1.Полученные допуски -99% (личные) 2. LTIF = 0 (ППЭ) 3. 0 пробитых барьеров при проведении стресс-тестов со стороны ОТ,ПБ (в ЗО смены) 4. ИА 1,2 = 0 | K11: Минимизация травматизма (LTIF) | L11: Качественная | M11: Контракт | N11: ТНХ 2026 | O11: =INDEX('список ID из СУЭ с должностями'!$A:$F,MATCH(E11,'список ID из СУЭ с должностями'!$B:$B,0),5) -> НС
A12: 3 квартал 2026 | B12: Год + квартал | C12: 2026 | D12: 01.07.2026 - 30.09.2026 | E12: 2 | F12: Начальник смены производства | G12: Общество с ограниченной ответственностью "Томскнефтехим"/Направление Директора по производству/Производство полиэтилена/Смена 3 | H12: Базовые обязательства | I12: HR Средний срок получения допуска к рабочему месту в ЗО не более 120 дней | J12: не более 120 дней | K12: Повышение производственной эффективности | L12: Количественная | M12: Контракт | N12: ТНХ 2026 | O12: =INDEX('список ID из СУЭ с должностями'!$A:$F,MATCH(E12,'список ID из СУЭ с должностями'!$B:$B,0),5) -> НС
A13: 3 квартал 2026 | B13: Год + квартал | C13: 2026 | D13: 01.07.2026 - 30.09.2026 | E13: 2 | F13: Начальник смены производства | G13: Общество с ограниченной ответственностью "Томскнефтехим"/Направление Директора по производству/Производство полиэтилена/Смена 3 | H13: Базовые обязательства | I13: Выполнение целей по качеству: - объем выпуска НСП | J13: КПОиТП не более 0,50 КЦП не менее 0,97 НСП более 5.97% | K13: Минимизация потерь | L13: Качественная | M13: Контракт | N13: ТНХ 2026 | O13: =INDEX('список ID из СУЭ с должностями'!$A:$F,MATCH(E13,'список ID из СУЭ с должностями'!$B:$B,0),5) -> НС
... A161: 3 квартал 2026 | B161: Год + квартал | C161: 2026 | D161: 01.07.2026 - 30.09.2026 | E161: 22 | F161: Специалист | G161: Общество с ограниченной ответственностью "Томскнефтехим"/Направление Директора по производству/Производство полиэтилена | H161: Задачи с эффектом в текущем году | I161: Соблюдение финансовой и исполнительной дисциплины | J161: График расчета заработной платы дневного персонала производства. | K161: Выполнение ключевых финансово-экономических показателей | L161: Качественная | M161: Контракт | N161: ТНХ 2026 | O161: =INDEX('список ID из СУЭ с должностями'!$A:$F,MATCH(E161,'список ID из СУЭ с должностями'!$B:$B,0),5) -> 0
A162: 3 квартал 2026 | B162: Год + квартал | C162: 2026 | D162: 01.07.2026 - 30.09.2026 | E162: 22 | F162: Специалист | G162: Общество с ограниченной ответственностью "Томскнефтехим"/Направление Директора по производству/Производство полиэтилена | H162: Долгосрочные цели | I162: Качество планирования | K162: Обеспечить приживаемость Производственной системы | L162: Качественная | M162: Контракт | N162: ТНХ 2026 | O162: =INDEX('список ID из СУЭ с должностями'!$A:$F,MATCH(E162,'список ID из СУЭ с должностями'!$B:$B,0),5) -> 0
A163: 3 квартал 2026 | B163: Год + квартал | C163: 2026 | D163: 01.07.2026 - 30.09.2026 | E163: 22 | F163: Специалист | G163: Общество с ограниченной ответственностью "Томскнефтехим"/Направление Директора по производству/Производство полиэтилена | H163: Базовые обязательства | I163: Качество ведения документооборота | J163: Своевременный пересмотр документации производства | K163: Обеспечить приживаемость Производственной системы | L163: Качественная | M163: Контракт | N163: ТНХ 2026 | O163: =INDEX('список ID из СУЭ с должностями'!$A:$F,MATCH(E163,'список ID из СУЭ с должностями'!$B:$B,0),5) -> 0
A164: 3 квартал 2026 | B164: Год + квартал | C164: 2026 | D164: 01.07.2026 - 30.09.2026 | E164: 23 | F164: Инженер по качеству испытаний | G164: Общество с ограниченной ответственностью "Томскнефтехим"/Служба главного технолога/Центральная заводская лаборатория | H164: Долгосрочные цели | I164: Применение ИИ в ЦЗЛ | J164: Генерация и реализация не менее 2-х процессов ЦЗЛ через ИИ | K164: Внедрение и обеспечение приживаемости инструментов ИИ | L164: Качественная | M164: Доп цели | N164: ТНХ 2026 | O164: =INDEX('список ID из СУЭ с должностями'!$A:$F,MATCH(E164,'список ID из СУЭ с должностями'!$B:$B,0),5) -> 0
A165: 3 квартал 2026 | B165: Год + квартал | C165: 2026 | D165: 01.07.2026 - 30.09.2026 | E165: 23 | F165: Инженер по качеству испытаний | G165: Общество с ограниченной ответственностью "Томскнефтехим"/Служба главного технолога/Центральная заводская лаборатория | H165: Базовые обязательства | I165: Подтверждение компетентности при аудите GMP | J165: Подготовка к аудиту, координация работ, отсутствие замечаний по процедурам ЦЗЛ | K165: Реализация производственного плана Не менее 426.1 тыс. тн | L165: Качественная | M165: Контракт | N165: ТНХ 2026 | O165: =INDEX('список ID из СУЭ с должностями'!$A:$F,MATCH(E165,'список ID из СУЭ с должностями'!$B:$B,0),5) -> 0
A166: 3 квартал 2026 | B166: Год + квартал | C166: 2026 | D166: 01.07.2026 - 30.09.2026 | E166: 23 | F166: Инженер по качеству испытаний | G166: Общество с ограниченной ответственностью "Томскнефтехим"/Служба главного технолога/Центральная заводская лаборатория | H166: Задачи с эффектом в текущем году | I166: Реализация программы развития ПСС | J166: Выполнение мероприятий по помещениям СЭК. Обучение в ЛК по СРР | K166: Обеспечить приживаемость Производственной системы | L166: Качественная | M166: Контракт | N166: ТНХ 2026 | O166: =INDEX('список ID из СУЭ с должностями'!$A:$F,MATCH(E166,'список ID из СУЭ с должностями'!$B:$B,0),5) -> 0
A167: 3 квартал 2026 | B167: Год + квартал | C167: 2026 | D167: 01.07.2026 - 30.09.2026 | E167: 23 | F167: Инженер по качеству испытаний | G167: Общество с ограниченной ответственностью "Томскнефтехим"/Служба главного технолога/Центральная заводская лаборатория | H167: Задачи с эффектом в текущем году | I167: Эффективное использование программы ЛИМС | J167: Организация работ по доработке Протокола испытаний в области аккредитации. Отсутствие замечаний по процедурам | K167: Реализация производственного плана Не менее 426.1 тыс. тн | L167: Качественная | M167: Контракт | N167: ТНХ 2026 | O167: =INDEX('список ID из СУЭ с должностями'!$A:$F,MATCH(E167,'список ID из СУЭ с должностями'!$B:$B,0),5) -> 0
A168: 3 квартал 2026 | B168: Год + квартал | C168: 2026 | D168: 01.07.2026 - 30.09.2026 | E168: 23 | F168: Инженер по качеству испытаний | G168: Общество с ограниченной ответственностью "Томскнефтехим"/Служба главного технолога/Центральная заводская лаборатория | H168: Задачи с эффектом в текущем году | I168: Развитие технических и функциональных компетенций персонала, в т.ч. по СМ | J168: Техническое обучение, проверка знаний, проработка кейсов по несоответствующим работам | K168: Реализация производственного плана Не менее 426.1 тыс. тн | L168: Качественная | M168: Контракт | N168: ТНХ 2026 | O168: =INDEX('список ID из СУЭ с должностями'!$A:$F,MATCH(E168,'список ID из СУЭ с должностями'!$B:$B,0),5) -> 0
A169: 3 квартал 2026 | B169: Год + квартал | C169: 2026 | D169: 01.07.2026 - 30.09.2026 | E169: 23 | F169: Инженер по качеству испытаний | G169: Общество с ограниченной ответственностью "Томскнефтехим"/Служба главного технолога/Центральная заводская лаборатория | H169: Базовые обязательства | I169: Развитие Системы менеджмента. Повышение результативности СМ | J169: 100% выполнение плана по повышению СМ | K169: Реализация производственного плана Не менее 426.1 тыс. тн | L169: Качественная | M169: Контракт | N169: ТНХ 2026 | O169: =INDEX('список ID из СУЭ с должностями'!$A:$F,MATCH(E169,'список ID из СУЭ с должностями'!$B:$B,0),5) -> 0
A170: 3 квартал 2026 | B170: Год + квартал | C170: 2026 | D170: 01.07.2026 - 30.09.2026 | E170: 23 | F170: Инженер по качеству испытаний | G170: Общество с ограниченной ответственностью "Томскнефтехим"/Служба главного технолога/Центральная заводская лаборатория | H170: Базовые обязательства | I170: Поддержание Культуры безопасности и экологичности в подразделении | J170: Вовлеченность сотрудников ЦЗЛ на уровне не ниже 100% - ЧБ, Экологии | K170: Минимизация травматизма (LTIF) | L170: Качественная | M170: Контракт | N170: ТНХ 2026 | O170: =INDEX('список ID из СУЭ с должностями'!$A:$F,MATCH(E170,'список ID из СУЭ с должностями'!$B:$B,0),5) -> 0
A171: 3 квартал 2026 | B171: Год + квартал | C171: 2026 | D171: 01.07.2026 - 30.09.2026 | E171: 23 | F171: Инженер по качеству испытаний | G171: Общество с ограниченной ответственностью "Томскнефтехим"/Служба главного технолога/Центральная заводская лаборатория | H171: Задачи с эффектом в текущем году | I171: Автоматизация результатов измерений аутсорсинговой лабораторий | J171: Результаты вносятся КА в систему ЛИМС, производство оперативно получает результат измерений | K171: Выполнение целей стратегии устойчивого развития, % Не менее 100 % | L171: Качественная | M171: Контракт | N171: ТНХ 2026 | O171: =INDEX('список ID из СУЭ с должностями'!$A:$F,MATCH(E171,'список ID из СУЭ с должностями'!$B:$B,0),5) -> 0
A172: 3 квартал 2026 | B172: Год + квартал | C172: 2026 | D172: 01.07.2026 - 30.09.2026 | E172: 23 | F172: Инженер по качеству испытаний | G172: Общество с ограниченной ответственностью "Томскнефтехим"/Служба главного технолога/Центральная заводская лаборатория | H172: Базовые обязательства | I172: Успешное проведение ОР 2026 в зоне ответственности | J172: 100% выполнение ГАК в зоне ответственности, организация оперативной доставки проб и выдачи результатов | K172: Успешное выполнение остановочного ремонта 2026 года | L172: Качественная | M172: Контракт | N172: ТНХ 2026 | O172: =INDEX('список ID из СУЭ с должностями'!$A:$F,MATCH(E172,'список ID из СУЭ с должностями'!$B:$B,0),5) -> 0
A173: 3 квартал 2026 | B173: Год + квартал | C173: 2026 | D173: 01.07.2026 - 30.09.2026 | E173: 23 | F173: Инженер по качеству испытаний | G173: Общество с ограниченной ответственностью "Томскнефтехим"/Служба главного технолога/Центральная заводская лаборатория | H173: Задачи с эффектом в текущем году | I173: Проект ТИБА- организация выполнение добавленного объема текущим ресурсом | J173: Сформирован ГАК на период пуска и стабильной работы с учетом рисков по качеству и трудозатратам ЦЗЛ | K173: Повышение производственной эффективности | L173: Качественная | M173: Контракт | N173: ТНХ 2026 | O173: =INDEX('список ID из СУЭ с должностями'!$A:$F,MATCH(E173,'список ID из СУЭ с должностями'!$B:$B,0),5) -> 0
A174: 3 квартал 2026 | B174: Год + квартал | C174: 2026 | D174: 01.07.2026 - 30.09.2026 | E174: 24 | F174: Инженер по автоматизации | G174: Общество с ограниченной ответственностью "Томскнефтехим"/Направление Главного инженера/Направление заместителя главного инженера/Служба управления основными фондами/Отдел технического обслуживания и ремонтов/Техническое обслуживание и ремонты Производства полипропилена | H174: Базовые обязательства | I174: Управление ремонтом -Автоматизация ПП | J174: Внесение в БДО новых ЕО, в рамках реализации проекта АСУТП и ЛСУ экструдера Р2.2 | K174: Повышение производственной эффективности | L174: Качественная | M174: Контракт | N174: ТНХ 2026 | O174: =INDEX('список ID из СУЭ с должностями'!$A:$F,MATCH(E174,'список ID из СУЭ с должностями'!$B:$B,0),5) -> 0
... A288: 3 квартал 2026 | B288: Год + квартал | C288: 2026 | D288: 01.07.2026 - 30.09.2026 | E288: 38 | F288: Старший химик | G288: Общество с ограниченной ответственностью "Томскнефтехим"/Служба главного технолога/Центральная заводская лаборатория/Смена 1 | H288: Долгосрочные цели | I288: Развитие системы менеджмента в смене | J288: Знание и соблюдение РК сотрудников смены. Линеаризация и обеспечение приживаемости вводимых процессов в смене | K288: Повышение производственной эффективности | L288: Качественная | M288: Контракт | N288: ТНХ 2026 | O288: =INDEX('список ID из СУЭ с должностями'!$A:$F,MATCH(E288,'список ID из СУЭ с должностями'!$B:$B,0),5) -> 0
A289: 3 квартал 2026 | B289: Год + квартал | C289: 2026 | D289: 01.07.2026 - 30.09.2026 | E289: 39 | F289: Эксперт | G289: Общество с ограниченной ответственностью "Томскнефтехим"/Направление Главного инженера/Служба управления надежностью/Лаборатория неразрушающего контроля и диагностики | H289: Базовые обязательства | I289: Минимизация травматизма (LTIF) | J289: 0 | K289: Минимизация травматизма (LTIF) | L289: Качественная | M289: Контракт | N289: ТНХ 2026 | O289: =INDEX('список ID из СУЭ с должностями'!$A:$F,MATCH(E289,'список ID из СУЭ с должностями'!$B:$B,0),5) -> 0
A290: 3 квартал 2026 | B290: Год + квартал | C290: 2026 | D290: 01.07.2026 - 30.09.2026 | E290: 39 | F290: Эксперт | G290: Общество с ограниченной ответственностью "Томскнефтехим"/Направление Главного инженера/Служба управления надежностью/Лаборатория неразрушающего контроля и диагностики | H290: Базовые обязательства | I290: Минимизация аварийности производственных объектов (ИА1) | J290: 0 | K290: Минимизация аварийности производственных объектов (ИА1) | L290: Качественная | M290: Контракт | N290: ТНХ 2026 | O290: =INDEX('список ID из СУЭ с должностями'!$A:$F,MATCH(E290,'список ID из СУЭ с должностями'!$B:$B,0),5) -> 0
A291: 3 квартал 2026 | B291: Год + квартал | C291: 2026 | D291: 01.07.2026 - 30.09.2026 | E291: 39 | F291: Эксперт | G291: Общество с ограниченной ответственностью "Томскнефтехим"/Направление Главного инженера/Служба управления надежностью/Лаборатория неразрушающего контроля и диагностики | H291: Задачи с эффектом в текущем году | I291: Успешное выполнение работ в период ОР-26 | J291: Работы выполнены безопасно и в срок. | K291: Успешное выполнение остановочного ремонта 2026 года | L291: Качественная | M291: Контракт | N291: ТНХ 2026 | O291: =INDEX('список ID из СУЭ с должностями'!$A:$F,MATCH(E291,'список ID из СУЭ с должностями'!$B:$B,0),5) -> 0
A292: 3 квартал 2026 | B292: Год + квартал | C292: 2026 | D292: 01.07.2026 - 30.09.2026 | E292: 39 | F292: Эксперт | G292: Общество с ограниченной ответственностью "Томскнефтехим"/Направление Главного инженера/Служба управления надежностью/Лаборатория неразрушающего контроля и диагностики | H292: Задачи с эффектом в текущем году | I292: Проведение СЭЗ и подтверждение лицензируемых требований для ИИИ | J292: Проведение независимой экспертизы с целью замены СЭЗ и регистрацией нового рентген аппарата, а так же подтверждение выполнения требований для лицензиата применяющий источники ионизирующего излучения. | K292: Выполнение целей стратегии устойчивого развития, % Не менее 100 % | L292: Качественная | M292: Контракт | N292: ТНХ 2026 | O292: =INDEX('список ID из СУЭ с должностями'!$A:$F,MATCH(E292,'список ID из СУЭ с должностями'!$B:$B,0),5) -> 0
A293: 3 квартал 2026 | B293: Год + квартал | C293: 2026 | D293: 01.07.2026 - 30.09.2026 | E293: 39 | F293: Эксперт | G293: Общество с ограниченной ответственностью "Томскнефтехим"/Направление Главного инженера/Служба управления надежностью/Лаборатория неразрушающего контроля и диагностики | H293: Задачи с эффектом в текущем году | I293: Приживаемость Производственной системы | J293: не менее 90 % | K293: Обеспечить приживаемость Производственной системы | L293: Количественная | M293: Контракт | N293: ТНХ 2026 | O293: =INDEX('список ID из СУЭ с должностями'!$A:$F,MATCH(E293,'список ID из СУЭ с должностями'!$B:$B,0),5) -> 0
A294: 3 квартал 2026 | B294: Год + квартал | C294: 2026 | D294: 01.07.2026 - 30.09.2026 | E294: 40 | F294: Специалист | G294: Общество с ограниченной ответственностью "Томскнефтехим"/Направление Главного инженера/Направление заместителя главного инженера/Управление материально-техническим обеспечением производства/Складское хозяйство | H294: Базовые обязательства | I294: Реализация УМШ | J294: не менее 1 Шт | K294: Повышение эффективности внутренних процессов функции | L294: Количественная | M294: Контракт | N294: ФОП 2026 | O294: =INDEX('список ID из СУЭ с должностями'!$A:$F,MATCH(E294,'список ID из СУЭ с должностями'!$B:$B,0),5) -> 0
A295: 3 квартал 2026 | B295: Год + квартал | C295: 2026 | D295: 01.07.2026 - 30.09.2026 | E295: 40 | F295: Специалист | G295: Общество с ограниченной ответственностью "Томскнефтехим"/Направление Главного инженера/Направление заместителя главного инженера/Управление материально-техническим обеспечением производства/Складское хозяйство | H295: Базовые обязательства | I295: Ознакомление с документами в системе КИС ЕСМ | J295: не менее 100 % | K295: Выполнение целей стратегии устойчивого развития, % Не менее 100 % | L295: Количественная | M295: Контракт | N295: ТНХ 2026 | O295: =INDEX('список ID из СУЭ с должностями'!$A:$F,MATCH(E295,'список ID из СУЭ с должностями'!$B:$B,0),5) -> 0
A296: 3 квартал 2026 | B296: Год + квартал | C296: 2026 | D296: 01.07.2026 - 30.09.2026 | E296: 40 | F296: Специалист | G296: Общество с ограниченной ответственностью "Томскнефтехим"/Направление Главного инженера/Направление заместителя главного инженера/Управление материально-техническим обеспечением производства/Складское хозяйство | H296: Базовые обязательства | I296: соблюдению чистоты в складе | J296: не менее 6 шт | K296: Повышение производственной эффективности | L296: Количественная | M296: Контракт | N296: ТНХ 2026 | O296: =INDEX('список ID из СУЭ с должностями'!$A:$F,MATCH(E296,'список ID из СУЭ с должностями'!$B:$B,0),5) -> 0
A297: 3 квартал 2026 | B297: Год + квартал | C297: 2026 | D297: 01.07.2026 - 30.09.2026 | E297: 40 | F297: Специалист | G297: Общество с ограниченной ответственностью "Томскнефтехим"/Направление Главного инженера/Направление заместителя главного инженера/Управление материально-техническим обеспечением производства/Складское хозяйство | H297: Задачи с эффектом в текущем году | I297: Проведение поведенческих аудитов (ПАБ) с выявлением ОУ и ОД, шт. | J297: не менее 3 шт | K297: Выполнение целей стратегии устойчивого развития, % Не менее 100 % | L297: Количественная | M297: Контракт | N297: ТНХ 2026 | O297: =INDEX('список ID из СУЭ с должностями'!$A:$F,MATCH(E297,'список ID из СУЭ с должностями'!$B:$B,0),5) -> 0
A298: 3 квартал 2026 | B298: Год + квартал | C298: 2026 | D298: 01.07.2026 - 30.09.2026 | E298: 40 | F298: Специалист | G298: Общество с ограниченной ответственностью "Томскнефтехим"/Направление Главного инженера/Направление заместителя главного инженера/Управление материально-техническим обеспечением производства/Складское хозяйство | H298: Базовые обязательства | I298: Наличие ШК и скан-копий в мониторе ФПД | J298: не менее 100 % | K298: Повышение производственной эффективности | L298: Количественная | M298: Контракт | N298: ТНХ 2026 | O298: =INDEX('список ID из СУЭ с должностями'!$A:$F,MATCH(E298,'список ID из СУЭ с должностями'!$B:$B,0),5) -> 0
A299: 3 квартал 2026 | B299: Год + квартал | C299: 2026 | D299: 01.07.2026 - 30.09.2026 | E299: 40 | F299: Специалист | G299: Общество с ограниченной ответственностью "Томскнефтехим"/Направление Главного инженера/Направление заместителя главного инженера/Управление материально-техническим обеспечением производства/Складское хозяйство | H299: Задачи с эффектом в текущем году | I299: Контроль несогласованного списания МТР с ЦС | J299: Списанные с ЦС МТР выданы заказчику или проведено сторно списанния | K299: Минимизация потерь | L299: Качественная | M299: Контракт | N299: ТНХ 2026 | O299: =INDEX('список ID из СУЭ с должностями'!$A:$F,MATCH(E299,'список ID из СУЭ с должностями'!$B:$B,0),5) -> 0
A300: 3 квартал 2026 | B300: Год + квартал | C300: 2026 | D300: 01.07.2026 - 30.09.2026 | E300: 40 | F300: Специалист | G300: Общество с ограниченной ответственностью "Томскнефтехим"/Направление Главного инженера/Направление заместителя главного инженера/Управление материально-техническим обеспечением производства/Складское хозяйство | H300: Базовые обязательства | I300: Контроль внесения конечного срока хранения МТР в признаки партии | J300: не менее 100 % | K300: Повышение эффективности внутренних процессов функции | L300: Количественная | M300: Контракт | N300: ФОП 2026 | O300: =INDEX('список ID из СУЭ с должностями'!$A:$F,MATCH(E300,'список ID из СУЭ с должностями'!$B:$B,0),5) -> 0
...

Sheet Лист1
A1: ТН сотрудника | B1: ИД сотрудника
A2: 23017551 | B2: 1
A3: 23000162 | B3: 2
A4: 23000229 | B4: 3
A5: 23000379 | B5: 4
A6: 23000394 | B6: 5
A7: 23000479 | B7: 6
A8: 23000507 | B8: 7
A9: 23000508 | B9: 8
A10: 23000797 | B10: 9
A11: 23001069 | B11: 10
A12: 23001120 | B12: 11
A13: 23001348 | B13: 12
... A548: 22077015 | B548: 547

Sheet список ID из СУЭ с должностями
A1: Принадлежность к СДП | B1: ID сотрудника | C1: Должность | D1: Подразделение
A2: =IF(ISNA(INDEX('ID относящиеся у производству'!A:A,MATCH(B2,'ID относящиеся у производству'!A:A,0),1))=TRUE,"НЕТ","ДА") -> НЕТ | B2: 1 | C2: Заместитель главного инженера | D2: Общество с ограниченной ответственностью "Томскнефтехим"/Направление Главного инженера/Направление заместителя главного инженера
A3: =IF(ISNA(INDEX('ID относящиеся у производству'!A:A,MATCH(B3,'ID относящиеся у производству'!A:A,0),1))=TRUE,"НЕТ","ДА") -> ДА | B3: 2 | C3: Начальник смены производства | D3: Общество с ограниченной ответственностью "Томскнефтехим"/Направление Директора по производству/Производство полиэтилена/Смена 3 | E3: НС | F3: СДП
A4: =IF(ISNA(INDEX('ID относящиеся у производству'!A:A,MATCH(B4,'ID относящиеся у производству'!A:A,0),1))=TRUE,"НЕТ","ДА") -> НЕТ | B4: 3 | C4: Эксперт | D4: Общество с ограниченной ответственностью "Томскнефтехим"/Направление Директора по управлению персоналом
A5: =IF(ISNA(INDEX('ID относящиеся у производству'!A:A,MATCH(B5,'ID относящиеся у производству'!A:A,0),1))=TRUE,"НЕТ","ДА") -> НЕТ | B5: 4 | C5: Ведущий специалист | D5: Общество с ограниченной ответственностью "Томскнефтехим"/Направление Главного инженера/Направление заместителя главного инженера/Служба управления основными фондами/Отдел планирования и контроля
A6: =IF(ISNA(INDEX('ID относящиеся у производству'!A:A,MATCH(B6,'ID относящиеся у производству'!A:A,0),1))=TRUE,"НЕТ","ДА") -> НЕТ | B6: 5 | C6: Эксперт | D6: Общество с ограниченной ответственностью "Томскнефтехим"/Направление Главного инженера/Направление заместителя главного инженера/Управление материально-техническим обеспечением производства/Отдел закупок материально-технических ресурсов и реализации невостребованного имущества
A7: =IF(ISNA(INDEX('ID относящиеся у производству'!A:A,MATCH(B7,'ID относящиеся у производству'!A:A,0),1))=TRUE,"НЕТ","ДА") -> НЕТ | B7: 6 | C7: Специалист | D7: Общество с ограниченной ответственностью "Томскнефтехим"/Направление Главного инженера/Направление заместителя главного инженера/Управление материально-техническим обеспечением производства/Складское хозяйство
A8: =IF(ISNA(INDEX('ID относящиеся у производству'!A:A,MATCH(B8,'ID относящиеся у производству'!A:A,0),1))=TRUE,"НЕТ","ДА") -> НЕТ | B8: 7 | C8: Инженер по метрологии | D8: Общество с ограниченной ответственностью "Томскнефтехим"/Направление Главного инженера/Направление заместителя главного инженера/Ремонтное производство/Ремонтное производство по ТОиР КИПиА, АСУ ТП Производств: мономеров, полиэтилена, полипропилена/Метрологическая лаборатория
A9: =IF(ISNA(INDEX('ID относящиеся у производству'!A:A,MATCH(B9,'ID относящиеся у производству'!A:A,0),1))=TRUE,"НЕТ","ДА") -> НЕТ | B9: 8 | C9: Инженер по метрологии | D9: Общество с ограниченной ответственностью "Томскнефтехим"/Направление Главного инженера/Направление заместителя главного инженера/Ремонтное производство/Ремонтное производство по ТОиР КИПиА, АСУ ТП Производств: мономеров, полиэтилена, полипропилена/Метрологическая лаборатория
A10: =IF(ISNA(INDEX('ID относящиеся у производству'!A:A,MATCH(B10,'ID относящиеся у производству'!A:A,0),1))=TRUE,"НЕТ","ДА") -> НЕТ | B10: 9 | C10: Химик | D10: Общество с ограниченной ответственностью "Томскнефтехим"/Служба главного технолога/Центральная заводская лаборатория/Смена 1
A11: =IF(ISNA(INDEX('ID относящиеся у производству'!A:A,MATCH(B11,'ID относящиеся у производству'!A:A,0),1))=TRUE,"НЕТ","ДА") -> ДА | B11: 10 | C11: Эксперт | D11: Общество с ограниченной ответственностью "Томскнефтехим"/Направление Директора по производству/Производство полиэтилена
A12: =IF(ISNA(INDEX('ID относящиеся у производству'!A:A,MATCH(B12,'ID относящиеся у производству'!A:A,0),1))=TRUE,"НЕТ","ДА") -> ДА | B12: 11 | C12: Инженер | D12: Общество с ограниченной ответственностью "Томскнефтехим"/Направление Директора по производству/Производство полипропилена/Смена 2 | E12: Инж смены | F12: СДП
A13: =IF(ISNA(INDEX('ID относящиеся у производству'!A:A,MATCH(B13,'ID относящиеся у производству'!A:A,0),1))=TRUE,"НЕТ","ДА") -> НЕТ | B13: 12 | C13: Химик | D13: Общество с ограниченной ответственностью "Томскнефтехим"/Служба главного технолога/Центральная заводская лаборатория/Смена 4
A14: =IF(ISNA(INDEX('ID относящиеся у производству'!A:A,MATCH(B14,'ID относящиеся у производству'!A:A,0),1))=TRUE,"НЕТ","ДА") -> НЕТ | B14: 13 | C14: Химик | D14: Общество с ограниченной ответственностью "Томскнефтехим"/Служба главного технолога/Центральная заводская лаборатория/Смена 3
A15: =IF(ISNA(INDEX('ID относящиеся у производству'!A:A,MATCH(B15,'ID относящиеся у производству'!A:A,0),1))=TRUE,"НЕТ","ДА") -> НЕТ | B15: 14 | C15: Ведущий инженер-химик | D15: Общество с ограниченной ответственностью "Томскнефтехим"/Служба главного технолога/Центральная заводская лаборатория
A16: =IF(ISNA(INDEX('ID относящиеся у производству'!A:A,MATCH(B16,'ID относящиеся у производству'!A:A,0),1))=TRUE,"НЕТ","ДА") -> ДА | B16: 15 | C16: Инженер по подготовке производства | D16: Общество с ограниченной ответственностью "Томскнефтехим"/Направление Директора по производству/Производство полипропилена/Установка полимеризации пропилена | E16: ИПП | F16: СДП
A17: =IF(ISNA(INDEX('ID относящиеся у производству'!A:A,MATCH(B17,'ID относящиеся у производству'!A:A,0),1))=TRUE,"НЕТ","ДА") -> НЕТ | B17: 16 | C17: Старший химик | D17: Общество с ограниченной ответственностью "Томскнефтехим"/Служба главного технолога/Центральная заводская лаборатория
A18: =IF(ISNA(INDEX('ID относящиеся у производству'!A:A,MATCH(B18,'ID относящиеся у производству'!A:A,0),1))=TRUE,"НЕТ","ДА") -> НЕТ | B18: 17 | C18: Ведущий специалист | D18: Общество с ограниченной ответственностью "Томскнефтехим"/Направление Главного инженера/Направление заместителя главного инженера/Служба управления основными фондами/Отдел планирования и контроля
A19: =IF(ISNA(INDEX('ID относящиеся у производству'!A:A,MATCH(B19,'ID относящиеся у производству'!A:A,0),1))=TRUE,"НЕТ","ДА") -> ДА | B19: 18 | C19: Ведущий инженер | D19: Общество с ограниченной ответственностью "Томскнефтехим"/Направление Директора по производству/Энергопроизводство/Установка теплопароснабжения | E19: ВИП | F19: СДП
A20: =IF(ISNA(INDEX('ID относящиеся у производству'!A:A,MATCH(B20,'ID относящиеся у производству'!A:A,0),1))=TRUE,"НЕТ","ДА") -> НЕТ | B20: 19 | C20: Инженер | D20: Общество с ограниченной ответственностью "Томскнефтехим"/Направление Главного инженера/Направление заместителя главного инженера/Ремонтное производство/Ремонтное производство по изготовлению/Отдел технического контроля
A21: =IF(ISNA(INDEX('ID относящиеся у производству'!A:A,MATCH(B21,'ID относящиеся у производству'!A:A,0),1))=TRUE,"НЕТ","ДА") -> НЕТ | B21: 20 | C21: Менеджер | D21: Общество с ограниченной ответственностью "Томскнефтехим"/Направление Главного инженера/Направление заместителя главного инженера/Управление материально-техническим обеспечением производства/Отдел закупок материально-технических ресурсов и реализации невостребованного имущества
A22: =IF(ISNA(INDEX('ID относящиеся у производству'!A:A,MATCH(B22,'ID относящиеся у производству'!A:A,0),1))=TRUE,"НЕТ","ДА") -> НЕТ | B22: 21 | C22: Инженер-механик | D22: Общество с ограниченной ответственностью "Томскнефтехим"/Направление Первого заместителя Генерального директора – Главного инженера/Служба управления основными фондами/Отдел технического обслуживания и ремонтов/Техническое обслуживание и ремонты Производства углеводородов и сырья для пиролиза
A23: =IF(ISNA(INDEX('ID относящиеся у производству'!A:A,MATCH(B23,'ID относящиеся у производству'!A:A,0),1))=TRUE,"НЕТ","ДА") -> ДА | B23: 22 | C23: Специалист | D23: Общество с ограниченной ответственностью "Томскнефтехим"/Направление Директора по производству/Производство полиэтилена
A24: =IF(ISNA(INDEX('ID относящиеся у производству'!A:A,MATCH(B24,'ID относящиеся у производству'!A:A,0),1))=TRUE,"НЕТ","ДА") -> НЕТ | B24: 23 | C24: Инженер по качеству испытаний | D24: Общество с ограниченной ответственностью "Томскнефтехим"/Служба главного технолога/Центральная заводская лаборатория
A25: =IF(ISNA(INDEX('ID относящиеся у производству'!A:A,MATCH(B25,'ID относящиеся у производству'!A:A,0),1))=TRUE,"НЕТ","ДА") -> НЕТ | B25: 24 | C25: Инженер по автоматизации | D25: Общество с ограниченной ответственностью "Томскнефтехим"/Направление Главного инженера/Направление заместителя главного инженера/Служба управления основными фондами/Отдел технического обслуживания и ремонтов/Техническое обслуживание и ремонты Производства полипропилена
A26: =IF(ISNA(INDEX('ID относящиеся у производству'!A:A,MATCH(B26,'ID относящиеся у производству'!A:A,0),1))=TRUE,"НЕТ","ДА") -> НЕТ | B26: 25 | C26: Эксперт | D26: Общество с ограниченной ответственностью "Томскнефтехим"/Направление Главного инженера/Направление заместителя главного инженера/Служба управления основными фондами/Отдел проектирования
A27: =IF(ISNA(INDEX('ID относящиеся у производству'!A:A,MATCH(B27,'ID относящиеся у производству'!A:A,0),1))=TRUE,"НЕТ","ДА") -> НЕТ | B27: 26 | C27: Главный эксперт | D27: Общество с ограниченной ответственностью "Томскнефтехим"/Направление Главного инженера/Служба управления надежностью
A28: =IF(ISNA(INDEX('ID относящиеся у производству'!A:A,MATCH(B28,'ID относящиеся у производству'!A:A,0),1))=TRUE,"НЕТ","ДА") -> НЕТ | B28: 27 | C28: Ведущий инженер-технолог | D28: Общество с ограниченной ответственностью "Томскнефтехим"/Служба главного технолога/Отдел технологии и развития
A29: =IF(ISNA(INDEX('ID относящиеся у производству'!A:A,MATCH(B29,'ID относящиеся у производству'!A:A,0),1))=TRUE,"НЕТ","ДА") -> НЕТ | B29: 28 | C29: Инженер-технолог | D29: Общество с ограниченной ответственностью "Томскнефтехим"/Служба главного технолога/Отдел качества, стандартизации и технического регулирования
A30: =IF(ISNA(INDEX('ID относящиеся у производству'!A:A,MATCH(B30,'ID относящиеся у производству'!A:A,0),1))=TRUE,"НЕТ","ДА") -> НЕТ | B30: 29 | C30: Химик | D30: Общество с ограниченной ответственностью "Томскнефтехим"/Служба главного технолога/Центральная заводская лаборатория/Смена 2
A31: =IF(ISNA(INDEX('ID относящиеся у производству'!A:A,MATCH(B31,'ID относящиеся у производству'!A:A,0),1))=TRUE,"НЕТ","ДА") -> НЕТ | B31: 30 | C31: Инженер-технолог | D31: Общество с ограниченной ответственностью "Томскнефтехим"/Направление Главного инженера/Направление заместителя главного инженера/Ремонтное производство/Ремонтное производство по изготовлению
... A41: =IF(ISNA(INDEX('ID относящиеся у производству'!A:A,MATCH(B41,'ID относящиеся у производству'!A:A,0),1))=TRUE,"НЕТ","ДА") -> НЕТ | B41: 40 | C41: Специалист | D41: Общество с ограниченной ответственностью "Томскнефтехим"/Направление Главного инженера/Направление заместителя главного инженера/Управление материально-техническим обеспечением производства/Складское хозяйство
A42: =IF(ISNA(INDEX('ID относящиеся у производству'!A:A,MATCH(B42,'ID относящиеся у производству'!A:A,0),1))=TRUE,"НЕТ","ДА") -> ДА | B42: 41 | C42: Инженер по планированию и ресурсному обеспечению | D42: Общество с ограниченной ответственностью "Томскнефтехим"/Направление Директора по производству/Энергопроизводство | E42: ИПРО | F42: СДП
A43: =IF(ISNA(INDEX('ID относящиеся у производству'!A:A,MATCH(B43,'ID относящиеся у производству'!A:A,0),1))=TRUE,"НЕТ","ДА") -> НЕТ | B43: 42 | C43: Начальник отдела | D43: Общество с ограниченной ответственностью "Томскнефтехим"/Направление Главного инженера/Направление заместителя главного инженера/Ремонтное производство/Ремонтное производство по изготовлению/Отдел технического контроля
A44: =IF(ISNA(INDEX('ID относящиеся у производству'!A:A,MATCH(B44,'ID относящиеся у производству'!A:A,0),1))=TRUE,"НЕТ","ДА") -> ДА | B44: 43 | C44: Инженер | D44: Общество с ограниченной ответственностью "Томскнефтехим"/Направление Директора по производству/Производство мономеров/Смена 4/Установка пиролиза углеводородов нефти | E44: Инж смены | F44: СДП
A45: =IF(ISNA(INDEX('ID относящиеся у производству'!A:A,MATCH(B45,'ID относящиеся у производству'!A:A,0),1))=TRUE,"НЕТ","ДА") -> НЕТ | B45: 44 | C45: Диспетчер | D45: Общество с ограниченной ответственностью "Томскнефтехим"/Производственно-диспетчерское управление
A46: =IF(ISNA(INDEX('ID относящиеся у производству'!A:A,MATCH(B46,'ID относящиеся у производству'!A:A,0),1))=TRUE,"НЕТ","ДА") -> НЕТ | B46: 45 | C46: Старший химик | D46: Общество с ограниченной ответственностью "Томскнефтехим"/Служба главного технолога/Центральная заводская лаборатория
A47: =IF(ISNA(INDEX('ID относящиеся у производству'!A:A,MATCH(B47,'ID относящиеся у производству'!A:A,0),1))=TRUE,"НЕТ","ДА") -> ДА | B47: 46 | C47: Инженер по планированию и ресурсному обеспечению | D47: Общество с ограниченной ответственностью "Томскнефтехим"/Направление Директора по производству/Производство мономеров | E47: ИПРО | F47: СДП
A48: =IF(ISNA(INDEX('ID относящиеся у производству'!A:A,MATCH(B48,'ID относящиеся у производству'!A:A,0),1))=TRUE,"НЕТ","ДА") -> НЕТ | B48: 47 | C48: Диспетчер | D48: Общество с ограниченной ответственностью "Томскнефтехим"/Производственно-диспетчерское управление
A49: =IF(ISNA(INDEX('ID относящиеся у производству'!A:A,MATCH(B49,'ID относящиеся у производству'!A:A,0),1))=TRUE,"НЕТ","ДА") -> НЕТ | B49: 48 | C49: Химик | D49: Общество с ограниченной ответственностью "Томскнефтехим"/Служба главного технолога/Центральная заводская лаборатория/Смена 2
...

Sheet ID относящиеся у производству
A1: 2
A2: 10
A3: 11
A4: 15
A5: 18
A6: 22
A7: 31
A8: 35
A9: 41
A10: 43
A11: 46
A12: 50
... A116: 542

Sheet ключи должностей к матрице
B2: СДП | O2: СГИ | AA2: СГТ и ЦЗЛ
B3: ДПП/ ДЗ | C3: МОК | D3: НП | E3: СМП | F3: 5НС | G3: ВИП | H3: Инж. по качеству | I3: ИПП | J3: ИПРО | K3: НС | L3: Инж смены | M3: Операторы пульта | N3: Операторы поля | O3: ГИ | P3: рук СУН | Q3: Работники СУН | R3: рук СУОФ | S3: рук ТОиР | T3: работники ТОиР | U3: рук РП | V3: НУ РП | W3: рем.персонал | X3: Рук ПО | Y3: РП ПО | Z3: рук ОР | AA3: ГТ | AB3: МТиР | AC3: ВИТ | AD3: ЭМ | AE3: МПП/ЭПП | AF3: МпоКачеству | AG3: Станарт | AH3: Эксперт по стандартизации | AI3: рук ЦЗЛ | AJ3: Химимки
B4: директор по производству | C4: менеджер по обеспечению компетенций | D4: начальник производства | E4: старший менеджер производства | F4: пятый начальник смены | G4: ведущий инженер производства | H4: инженер по качеству | I4: инженер по подготовке производства | J4: инженер по ресурсному обеспечению | K4: начальник смены | L4: инженер смены | O4: главный инженер | P4: рук службы управления надежнотью | Q4: принадлежность к службе упр надежностью | AA4: главный технолог | AC4: ведущий инеженер технолог | AD4: энергоменеджер
B5: директор завода
